
Internal Server Error: /api/trial-days/
Traceback (most recent call last):
  File "/usr/local/lib/python3.10/site-packages/django/db/backends/utils.py", line 89, in _execute
    return self.cursor.execute(sql, params)
psycopg2.errors.UndefinedTable: relation "core_trialdays" does not exist
LINE 1: ...ore_trialdays"."id", "core_trialdays"."days" FROM "core_tria...
                                                             ^


The above exception was the direct cause of the following exception:

Traceback (most recent call last):
  File "/usr/local/lib/python3.10/site-packages/django/core/handlers/exception.py", line 55, in inner
    response = get_response(request)
  File "/usr/local/lib/python3.10/site-packages/django/core/handlers/base.py", line 197, in _get_response
    response = wrapped_callback(request, *callback_args, **callback_kwargs)
  File "/usr/local/lib/python3.10/site-packages/django/views/decorators/csrf.py", line 54, in wrapped_view
    return view_func(*args, **kwargs)
  File "/usr/local/lib/python3.10/site-packages/django/views/generic/base.py", line 103, in view
    return self.dispatch(request, *args, **kwargs)
  File "/usr/local/lib/python3.10/site-packages/rest_framework/views.py", line 509, in dispatch
    response = self.handle_exception(exc)
  File "/usr/local/lib/python3.10/site-packages/rest_framework/views.py", line 469, in handle_exception
    self.raise_uncaught_exception(exc)
  File "/usr/local/lib/python3.10/site-packages/rest_framework/views.py", line 480, in raise_uncaught_exception
    raise exc
  File "/usr/local/lib/python3.10/site-packages/rest_framework/views.py", line 506, in dispatch
    response = handler(request, *args, **kwargs)
  File "/usr/src/app/core/views.py", line 257, in get
    return Response(serializer.data)
  File "/usr/local/lib/python3.10/site-packages/rest_framework/serializers.py", line 768, in data
    ret = super().data
  File "/usr/local/lib/python3.10/site-packages/rest_framework/serializers.py", line 253, in data
    self._data = self.to_representation(self.instance)
  File "/usr/local/lib/python3.10/site-packages/rest_framework/serializers.py", line 686, in to_representation
    return [
  File "/usr/local/lib/python3.10/site-packages/django/db/models/query.py", line 394, in __iter__
    self._fetch_all()
  File "/usr/local/lib/python3.10/site-packages/django/db/models/query.py", line 1866, in _fetch_all
    self._result_cache = list(self._iterable_class(self))
  File "/usr/local/lib/python3.10/site-packages/django/db/models/query.py", line 87, in __iter__
    results = compiler.execute_sql(
  File "/usr/local/lib/python3.10/site-packages/django/db/models/sql/compiler.py", line 1398, in execute_sql
    cursor.execute(sql, params)
  File "/usr/local/lib/python3.10/site-packages/django/db/backends/utils.py", line 103, in execute
    return super().execute(sql, params)
  File "/usr/local/lib/python3.10/site-packages/django/db/backends/utils.py", line 67, in execute
    return self._execute_with_wrappers(
  File "/usr/local/lib/python3.10/site-packages/django/db/backends/utils.py", line 80, in _execute_with_wrappers
    return executor(sql, params, many, context)
  File "/usr/local/lib/python3.10/site-packages/django/db/backends/utils.py", line 84, in _execute
    with self.db.wrap_database_errors:
  File "/usr/local/lib/python3.10/site-packages/django/db/utils.py", line 91, in __exit__
    raise dj_exc_value.with_traceback(traceback) from exc_value
  File "/usr/local/lib/python3.10/site-packages/django/db/backends/utils.py", line 89, in _execute
    return self.cursor.execute(sql, params)
django.db.utils.ProgrammingError: relation "core_trialdays" does not exist
LINE 1: ...ore_trialdays"."id", "core_trialdays"."days" FROM "core_tria...
                                                             ^

"GET /api/trial-days/ HTTP/1.1" 500 148787
Internal Server Error: /api/sign_up/
Traceback (most recent call last):
  File "/usr/local/lib/python3.10/site-packages/django/db/backends/utils.py", line 89, in _execute
    return self.cursor.execute(sql, params)
psycopg2.errors.UndefinedTable: relation "core_customuser" does not exist
LINE 1: SELECT 1 AS "a" FROM "core_customuser" WHERE "core_customuse...
                             ^


The above exception was the direct cause of the following exception:

Traceback (most recent call last):
  File "/usr/local/lib/python3.10/site-packages/django/core/handlers/exception.py", line 55, in inner
    response = get_response(request)
  File "/usr/local/lib/python3.10/site-packages/django/core/handlers/base.py", line 197, in _get_response
    response = wrapped_callback(request, *callback_args, **callback_kwargs)
  File "/usr/local/lib/python3.10/site-packages/django/views/decorators/csrf.py", line 54, in wrapped_view
    return view_func(*args, **kwargs)
  File "/usr/local/lib/python3.10/site-packages/django/views/generic/base.py", line 103, in view
    return self.dispatch(request, *args, **kwargs)
  File "/usr/local/lib/python3.10/site-packages/django/utils/decorators.py", line 46, in _wrapper
    return bound_method(*args, **kwargs)
  File "/usr/local/lib/python3.10/site-packages/rest_framework/views.py", line 509, in dispatch
    response = self.handle_exception(exc)
  File "/usr/local/lib/python3.10/site-packages/rest_framework/views.py", line 469, in handle_exception
    self.raise_uncaught_exception(exc)
  File "/usr/local/lib/python3.10/site-packages/rest_framework/views.py", line 480, in raise_uncaught_exception
    raise exc
  File "/usr/local/lib/python3.10/site-packages/rest_framework/views.py", line 506, in dispatch
    response = handler(request, *args, **kwargs)
  File "/usr/local/lib/python3.10/site-packages/rest_framework/generics.py", line 190, in post
    return self.create(request, *args, **kwargs)
  File "/usr/src/app/core/views.py", line 54, in create
    if not serializer.is_valid():
  File "/usr/local/lib/python3.10/site-packages/rest_framework/serializers.py", line 227, in is_valid
    self._validated_data = self.run_validation(self.initial_data)
  File "/usr/local/lib/python3.10/site-packages/rest_framework/serializers.py", line 426, in run_validation
    value = self.to_internal_value(data)
  File "/usr/local/lib/python3.10/site-packages/rest_framework/serializers.py", line 483, in to_internal_value
    validated_value = field.run_validation(primitive_value)
  File "/usr/local/lib/python3.10/site-packages/rest_framework/fields.py", line 751, in run_validation
    return super().run_validation(data)
  File "/usr/local/lib/python3.10/site-packages/rest_framework/fields.py", line 548, in run_validation
    self.run_validators(value)
  File "/usr/local/lib/python3.10/site-packages/rest_framework/fields.py", line 560, in run_validators
    validator(value, self)
  File "/usr/local/lib/python3.10/site-packages/rest_framework/validators.py", line 73, in __call__
    if qs_exists(queryset):
  File "/usr/local/lib/python3.10/site-packages/rest_framework/validators.py", line 21, in qs_exists
    return queryset.exists()
  File "/usr/local/lib/python3.10/site-packages/django/db/models/query.py", line 1225, in exists
    return self.query.has_results(using=self.db)
  File "/usr/local/lib/python3.10/site-packages/django/db/models/sql/query.py", line 592, in has_results
    return compiler.has_results()
  File "/usr/local/lib/python3.10/site-packages/django/db/models/sql/compiler.py", line 1366, in has_results
    return bool(self.execute_sql(SINGLE))
  File "/usr/local/lib/python3.10/site-packages/django/db/models/sql/compiler.py", line 1398, in execute_sql
    cursor.execute(sql, params)
  File "/usr/local/lib/python3.10/site-packages/django/db/backends/utils.py", line 103, in execute
    return super().execute(sql, params)
  File "/usr/local/lib/python3.10/site-packages/django/db/backends/utils.py", line 67, in execute
    return self._execute_with_wrappers(
  File "/usr/local/lib/python3.10/site-packages/django/db/backends/utils.py", line 80, in _execute_with_wrappers
    return executor(sql, params, many, context)
  File "/usr/local/lib/python3.10/site-packages/django/db/backends/utils.py", line 84, in _execute
    with self.db.wrap_database_errors:
  File "/usr/local/lib/python3.10/site-packages/django/db/utils.py", line 91, in __exit__
    raise dj_exc_value.with_traceback(traceback) from exc_value
  File "/usr/local/lib/python3.10/site-packages/django/db/backends/utils.py", line 89, in _execute
    return self.cursor.execute(sql, params)
django.db.utils.ProgrammingError: relation "core_customuser" does not exist
LINE 1: SELECT 1 AS "a" FROM "core_customuser" WHERE "core_customuse...
                             ^

"POST /api/sign_up/ HTTP/1.1" 500 185864
Internal Server Error: /api/password-reset/
Traceback (most recent call last):
  File "/usr/local/lib/python3.10/site-packages/django/core/handlers/exception.py", line 55, in inner
    response = get_response(request)
  File "/usr/local/lib/python3.10/site-packages/django/core/handlers/base.py", line 197, in _get_response
    response = wrapped_callback(request, *callback_args, **callback_kwargs)
  File "/usr/local/lib/python3.10/site-packages/django/views/decorators/csrf.py", line 54, in wrapped_view
    return view_func(*args, **kwargs)
  File "/usr/local/lib/python3.10/site-packages/django/views/generic/base.py", line 103, in view
    return self.dispatch(request, *args, **kwargs)
  File "/usr/local/lib/python3.10/site-packages/rest_framework/views.py", line 509, in dispatch
    response = self.handle_exception(exc)
  File "/usr/local/lib/python3.10/site-packages/rest_framework/views.py", line 469, in handle_exception
    self.raise_uncaught_exception(exc)
  File "/usr/local/lib/python3.10/site-packages/rest_framework/views.py", line 480, in raise_uncaught_exception
    raise exc
  File "/usr/local/lib/python3.10/site-packages/rest_framework/views.py", line 506, in dispatch
    response = handler(request, *args, **kwargs)
  File "/usr/src/app/core/views.py", line 149, in post
    reset_link = f'http://192.168.100.162:3001/#/reset-password/{uid.decode()}/{token}'
AttributeError: 'str' object has no attribute 'decode'
"POST /api/password-reset/ HTTP/1.1" 500 84196
Internal Server Error: /api/password-reset/
Traceback (most recent call last):
  File "/usr/local/lib/python3.10/site-packages/django/core/handlers/exception.py", line 55, in inner
    response = get_response(request)
  File "/usr/local/lib/python3.10/site-packages/django/core/handlers/base.py", line 197, in _get_response
    response = wrapped_callback(request, *callback_args, **callback_kwargs)
  File "/usr/local/lib/python3.10/site-packages/django/views/decorators/csrf.py", line 54, in wrapped_view
    return view_func(*args, **kwargs)
  File "/usr/local/lib/python3.10/site-packages/django/views/generic/base.py", line 103, in view
    return self.dispatch(request, *args, **kwargs)
  File "/usr/local/lib/python3.10/site-packages/rest_framework/views.py", line 509, in dispatch
    response = self.handle_exception(exc)
  File "/usr/local/lib/python3.10/site-packages/rest_framework/views.py", line 469, in handle_exception
    self.raise_uncaught_exception(exc)
  File "/usr/local/lib/python3.10/site-packages/rest_framework/views.py", line 480, in raise_uncaught_exception
    raise exc
  File "/usr/local/lib/python3.10/site-packages/rest_framework/views.py", line 506, in dispatch
    response = handler(request, *args, **kwargs)
  File "/usr/src/app/core/views.py", line 178, in post
    if response.status_code == 200:
AttributeError: 'str' object has no attribute 'status_code'
"POST /api/password-reset/ HTTP/1.1" 500 86897
Internal Server Error: /api/password-reset/
Traceback (most recent call last):
  File "/usr/local/lib/python3.10/site-packages/django/core/handlers/exception.py", line 55, in inner
    response = get_response(request)
  File "/usr/local/lib/python3.10/site-packages/django/core/handlers/base.py", line 197, in _get_response
    response = wrapped_callback(request, *callback_args, **callback_kwargs)
  File "/usr/local/lib/python3.10/site-packages/django/views/decorators/csrf.py", line 54, in wrapped_view
    return view_func(*args, **kwargs)
  File "/usr/local/lib/python3.10/site-packages/django/views/generic/base.py", line 103, in view
    return self.dispatch(request, *args, **kwargs)
  File "/usr/local/lib/python3.10/site-packages/rest_framework/views.py", line 509, in dispatch
    response = self.handle_exception(exc)
  File "/usr/local/lib/python3.10/site-packages/rest_framework/views.py", line 469, in handle_exception
    self.raise_uncaught_exception(exc)
  File "/usr/local/lib/python3.10/site-packages/rest_framework/views.py", line 480, in raise_uncaught_exception
    raise exc
  File "/usr/local/lib/python3.10/site-packages/rest_framework/views.py", line 506, in dispatch
    response = handler(request, *args, **kwargs)
  File "/usr/src/app/core/views.py", line 182, in post
    response = client.messages.send( message=message)
AttributeError: 'Client' object has no attribute 'messages'
"POST /api/password-reset/ HTTP/1.1" 500 86633
Internal Server Error: /api/trial-days/
Traceback (most recent call last):
  File "/usr/local/lib/python3.10/site-packages/django/db/backends/utils.py", line 89, in _execute
    return self.cursor.execute(sql, params)
psycopg2.errors.UndefinedTable: relation "core_trialdays" does not exist
LINE 1: ...ore_trialdays"."id", "core_trialdays"."days" FROM "core_tria...
                                                             ^


The above exception was the direct cause of the following exception:

Traceback (most recent call last):
  File "/usr/local/lib/python3.10/site-packages/django/core/handlers/exception.py", line 55, in inner
    response = get_response(request)
  File "/usr/local/lib/python3.10/site-packages/django/core/handlers/base.py", line 197, in _get_response
    response = wrapped_callback(request, *callback_args, **callback_kwargs)
  File "/usr/local/lib/python3.10/site-packages/django/views/decorators/csrf.py", line 54, in wrapped_view
    return view_func(*args, **kwargs)
  File "/usr/local/lib/python3.10/site-packages/django/views/generic/base.py", line 103, in view
    return self.dispatch(request, *args, **kwargs)
  File "/usr/local/lib/python3.10/site-packages/rest_framework/views.py", line 509, in dispatch
    response = self.handle_exception(exc)
  File "/usr/local/lib/python3.10/site-packages/rest_framework/views.py", line 469, in handle_exception
    self.raise_uncaught_exception(exc)
  File "/usr/local/lib/python3.10/site-packages/rest_framework/views.py", line 480, in raise_uncaught_exception
    raise exc
  File "/usr/local/lib/python3.10/site-packages/rest_framework/views.py", line 506, in dispatch
    response = handler(request, *args, **kwargs)
  File "/usr/src/app/core/views.py", line 264, in get
    return Response(serializer.data)
  File "/usr/local/lib/python3.10/site-packages/rest_framework/serializers.py", line 768, in data
    ret = super().data
  File "/usr/local/lib/python3.10/site-packages/rest_framework/serializers.py", line 253, in data
    self._data = self.to_representation(self.instance)
  File "/usr/local/lib/python3.10/site-packages/rest_framework/serializers.py", line 686, in to_representation
    return [
  File "/usr/local/lib/python3.10/site-packages/django/db/models/query.py", line 394, in __iter__
    self._fetch_all()
  File "/usr/local/lib/python3.10/site-packages/django/db/models/query.py", line 1866, in _fetch_all
    self._result_cache = list(self._iterable_class(self))
  File "/usr/local/lib/python3.10/site-packages/django/db/models/query.py", line 87, in __iter__
    results = compiler.execute_sql(
  File "/usr/local/lib/python3.10/site-packages/django/db/models/sql/compiler.py", line 1398, in execute_sql
    cursor.execute(sql, params)
  File "/usr/local/lib/python3.10/site-packages/django/db/backends/utils.py", line 103, in execute
    return super().execute(sql, params)
  File "/usr/local/lib/python3.10/site-packages/django/db/backends/utils.py", line 67, in execute
    return self._execute_with_wrappers(
  File "/usr/local/lib/python3.10/site-packages/django/db/backends/utils.py", line 80, in _execute_with_wrappers
    return executor(sql, params, many, context)
  File "/usr/local/lib/python3.10/site-packages/django/db/backends/utils.py", line 84, in _execute
    with self.db.wrap_database_errors:
  File "/usr/local/lib/python3.10/site-packages/django/db/utils.py", line 91, in __exit__
    raise dj_exc_value.with_traceback(traceback) from exc_value
  File "/usr/local/lib/python3.10/site-packages/django/db/backends/utils.py", line 89, in _execute
    return self.cursor.execute(sql, params)
django.db.utils.ProgrammingError: relation "core_trialdays" does not exist
LINE 1: ...ore_trialdays"."id", "core_trialdays"."days" FROM "core_tria...
                                                             ^

"GET /api/trial-days/ HTTP/1.1" 500 148967
Internal Server Error: /api/sign_up/
Traceback (most recent call last):
  File "/usr/local/lib/python3.10/site-packages/django/db/backends/utils.py", line 89, in _execute
    return self.cursor.execute(sql, params)
psycopg2.errors.UndefinedTable: relation "core_customuser" does not exist
LINE 1: SELECT 1 AS "a" FROM "core_customuser" WHERE "core_customuse...
                             ^


The above exception was the direct cause of the following exception:

Traceback (most recent call last):
  File "/usr/local/lib/python3.10/site-packages/django/core/handlers/exception.py", line 55, in inner
    response = get_response(request)
  File "/usr/local/lib/python3.10/site-packages/django/core/handlers/base.py", line 197, in _get_response
    response = wrapped_callback(request, *callback_args, **callback_kwargs)
  File "/usr/local/lib/python3.10/site-packages/django/views/decorators/csrf.py", line 54, in wrapped_view
    return view_func(*args, **kwargs)
  File "/usr/local/lib/python3.10/site-packages/django/views/generic/base.py", line 103, in view
    return self.dispatch(request, *args, **kwargs)
  File "/usr/local/lib/python3.10/site-packages/django/utils/decorators.py", line 46, in _wrapper
    return bound_method(*args, **kwargs)
  File "/usr/local/lib/python3.10/site-packages/rest_framework/views.py", line 509, in dispatch
    response = self.handle_exception(exc)
  File "/usr/local/lib/python3.10/site-packages/rest_framework/views.py", line 469, in handle_exception
    self.raise_uncaught_exception(exc)
  File "/usr/local/lib/python3.10/site-packages/rest_framework/views.py", line 480, in raise_uncaught_exception
    raise exc
  File "/usr/local/lib/python3.10/site-packages/rest_framework/views.py", line 506, in dispatch
    response = handler(request, *args, **kwargs)
  File "/usr/local/lib/python3.10/site-packages/rest_framework/generics.py", line 190, in post
    return self.create(request, *args, **kwargs)
  File "/usr/src/app/core/views.py", line 54, in create
    if not serializer.is_valid():
  File "/usr/local/lib/python3.10/site-packages/rest_framework/serializers.py", line 227, in is_valid
    self._validated_data = self.run_validation(self.initial_data)
  File "/usr/local/lib/python3.10/site-packages/rest_framework/serializers.py", line 426, in run_validation
    value = self.to_internal_value(data)
  File "/usr/local/lib/python3.10/site-packages/rest_framework/serializers.py", line 483, in to_internal_value
    validated_value = field.run_validation(primitive_value)
  File "/usr/local/lib/python3.10/site-packages/rest_framework/fields.py", line 751, in run_validation
    return super().run_validation(data)
  File "/usr/local/lib/python3.10/site-packages/rest_framework/fields.py", line 548, in run_validation
    self.run_validators(value)
  File "/usr/local/lib/python3.10/site-packages/rest_framework/fields.py", line 560, in run_validators
    validator(value, self)
  File "/usr/local/lib/python3.10/site-packages/rest_framework/validators.py", line 73, in __call__
    if qs_exists(queryset):
  File "/usr/local/lib/python3.10/site-packages/rest_framework/validators.py", line 21, in qs_exists
    return queryset.exists()
  File "/usr/local/lib/python3.10/site-packages/django/db/models/query.py", line 1225, in exists
    return self.query.has_results(using=self.db)
  File "/usr/local/lib/python3.10/site-packages/django/db/models/sql/query.py", line 592, in has_results
    return compiler.has_results()
  File "/usr/local/lib/python3.10/site-packages/django/db/models/sql/compiler.py", line 1366, in has_results
    return bool(self.execute_sql(SINGLE))
  File "/usr/local/lib/python3.10/site-packages/django/db/models/sql/compiler.py", line 1398, in execute_sql
    cursor.execute(sql, params)
  File "/usr/local/lib/python3.10/site-packages/django/db/backends/utils.py", line 103, in execute
    return super().execute(sql, params)
  File "/usr/local/lib/python3.10/site-packages/django/db/backends/utils.py", line 67, in execute
    return self._execute_with_wrappers(
  File "/usr/local/lib/python3.10/site-packages/django/db/backends/utils.py", line 80, in _execute_with_wrappers
    return executor(sql, params, many, context)
  File "/usr/local/lib/python3.10/site-packages/django/db/backends/utils.py", line 84, in _execute
    with self.db.wrap_database_errors:
  File "/usr/local/lib/python3.10/site-packages/django/db/utils.py", line 91, in __exit__
    raise dj_exc_value.with_traceback(traceback) from exc_value
  File "/usr/local/lib/python3.10/site-packages/django/db/backends/utils.py", line 89, in _execute
    return self.cursor.execute(sql, params)
django.db.utils.ProgrammingError: relation "core_customuser" does not exist
LINE 1: SELECT 1 AS "a" FROM "core_customuser" WHERE "core_customuse...
                             ^

"POST /api/sign_up/ HTTP/1.1" 500 186045
Internal Server Error: /api/password-reset/
"POST /api/password-reset/ HTTP/1.1" 500 52
Internal Server Error: /api/password-reset/
"POST /api/password-reset/ HTTP/1.1" 500 52
Internal Server Error: /api/password-reset/
"POST /api/password-reset/ HTTP/1.1" 500 52
Internal Server Error: /api/contact/5/
Traceback (most recent call last):
  File "/usr/local/lib/python3.10/site-packages/django/core/handlers/exception.py", line 55, in inner
    response = get_response(request)
  File "/usr/local/lib/python3.10/site-packages/django/core/handlers/base.py", line 197, in _get_response
    response = wrapped_callback(request, *callback_args, **callback_kwargs)
  File "/usr/local/lib/python3.10/site-packages/django/views/decorators/csrf.py", line 54, in wrapped_view
    return view_func(*args, **kwargs)
  File "/usr/local/lib/python3.10/site-packages/django/views/generic/base.py", line 103, in view
    return self.dispatch(request, *args, **kwargs)
  File "/usr/local/lib/python3.10/site-packages/rest_framework/views.py", line 511, in dispatch
    self.response = self.finalize_response(request, response, *args, **kwargs)
  File "/usr/local/lib/python3.10/site-packages/rest_framework/views.py", line 423, in finalize_response
    assert isinstance(response, HttpResponseBase), (
AssertionError: Expected a `Response`, `HttpResponse` or `HttpStreamingResponse` to be returned from the view, but received a `<class 'NoneType'>`
Internal Server Error: /api/contact/5/
Traceback (most recent call last):
  File "/usr/local/lib/python3.10/site-packages/django/core/handlers/exception.py", line 55, in inner
    response = get_response(request)
  File "/usr/local/lib/python3.10/site-packages/django/core/handlers/base.py", line 197, in _get_response
    response = wrapped_callback(request, *callback_args, **callback_kwargs)
  File "/usr/local/lib/python3.10/site-packages/django/views/decorators/csrf.py", line 54, in wrapped_view
    return view_func(*args, **kwargs)
  File "/usr/local/lib/python3.10/site-packages/django/views/generic/base.py", line 103, in view
    return self.dispatch(request, *args, **kwargs)
  File "/usr/local/lib/python3.10/site-packages/rest_framework/views.py", line 511, in dispatch
    self.response = self.finalize_response(request, response, *args, **kwargs)
  File "/usr/local/lib/python3.10/site-packages/rest_framework/views.py", line 423, in finalize_response
    assert isinstance(response, HttpResponseBase), (
AssertionError: Expected a `Response`, `HttpResponse` or `HttpStreamingResponse` to be returned from the view, but received a `<class 'NoneType'>`
Internal Server Error: /api/create_subscription/1/
"GET /api/create_subscription/1/ HTTP/1.1" 500 161
Internal Server Error: /api/create_subscription/1/
"GET /api/create_subscription/1/ HTTP/1.1" 500 161
Internal Server Error: /api/create_subscription/1/
"GET /api/create_subscription/1/ HTTP/1.1" 500 161
Internal Server Error: /stripe/webhook/
"POST /stripe/webhook/ HTTP/1.1" 500 281
Internal Server Error: /stripe/webhook/
"POST /stripe/webhook/ HTTP/1.1" 500 63
Internal Server Error: /api/create_subscription/1/
"GET /api/create_subscription/1/ HTTP/1.1" 500 161
Internal Server Error: /api/create_subscription/1/
"GET /api/create_subscription/1/ HTTP/1.1" 500 161
Internal Server Error: /api/create_subscription/1/
"GET /api/create_subscription/1/ HTTP/1.1" 500 161
Internal Server Error: /stripe/webhook/
"POST /stripe/webhook/ HTTP/1.1" 500 63
Internal Server Error: /api/create_subscription/1/
"GET /api/create_subscription/1/ HTTP/1.1" 500 161
Internal Server Error: /api/create_subscription/1/
"GET /api/create_subscription/1/ HTTP/1.1" 500 161
Error processing Stripe webhook: module 'datetime' has no attribute 'fromtimestamp'
Traceback (most recent call last):
  File "/usr/src/app/payments/views.py", line 381, in post
    self.send_trial_start_email(customer_email, subscription)
  File "/usr/src/app/payments/views.py", line 515, in send_trial_start_email
    readable_date = datetime.fromtimestamp(subscription.trial_end, datetime.timezone.utc).strftime('%Y-%m-%d %H:%M:%S')
AttributeError: module 'datetime' has no attribute 'fromtimestamp'
Internal Server Error: /stripe/webhook/
"POST /stripe/webhook/ HTTP/1.1" 500 63
Internal Server Error: /api/create_subscription/1/
"GET /api/create_subscription/1/ HTTP/1.1" 500 161
Internal Server Error: /api/log_in/
Traceback (most recent call last):
  File "/usr/local/lib/python3.10/site-packages/django/db/backends/utils.py", line 89, in _execute
    return self.cursor.execute(sql, params)
  File "/usr/local/lib/python3.10/site-packages/django/db/backends/sqlite3/base.py", line 357, in execute
    return Database.Cursor.execute(self, query, params)
sqlite3.OperationalError: no such table: core_customuser

The above exception was the direct cause of the following exception:

Traceback (most recent call last):
  File "/usr/src/app/core/views.py", line 76, in post
    serializer.is_valid(raise_exception=True)
  File "/usr/local/lib/python3.10/site-packages/rest_framework/serializers.py", line 227, in is_valid
    self._validated_data = self.run_validation(self.initial_data)
  File "/usr/local/lib/python3.10/site-packages/rest_framework/serializers.py", line 429, in run_validation
    value = self.validate(value)
  File "/usr/local/lib/python3.10/site-packages/rest_framework_simplejwt/serializers.py", line 68, in validate
    data = super().validate(attrs)
  File "/usr/local/lib/python3.10/site-packages/rest_framework_simplejwt/serializers.py", line 49, in validate
    self.user = authenticate(**authenticate_kwargs)
  File "/usr/local/lib/python3.10/site-packages/django/views/decorators/debug.py", line 42, in sensitive_variables_wrapper
    return func(*func_args, **func_kwargs)
  File "/usr/local/lib/python3.10/site-packages/django/contrib/auth/__init__.py", line 77, in authenticate
    user = backend.authenticate(request, **credentials)
  File "/usr/src/app/core/backends.py", line 11, in authenticate
    user = User.objects.get(
  File "/usr/local/lib/python3.10/site-packages/django/db/models/manager.py", line 85, in manager_method
    return getattr(self.get_queryset(), name)(*args, **kwargs)
  File "/usr/local/lib/python3.10/site-packages/django/db/models/query.py", line 646, in get
    num = len(clone)
  File "/usr/local/lib/python3.10/site-packages/django/db/models/query.py", line 376, in __len__
    self._fetch_all()
  File "/usr/local/lib/python3.10/site-packages/django/db/models/query.py", line 1866, in _fetch_all
    self._result_cache = list(self._iterable_class(self))
  File "/usr/local/lib/python3.10/site-packages/django/db/models/query.py", line 87, in __iter__
    results = compiler.execute_sql(
  File "/usr/local/lib/python3.10/site-packages/django/db/models/sql/compiler.py", line 1398, in execute_sql
    cursor.execute(sql, params)
  File "/usr/local/lib/python3.10/site-packages/django/db/backends/utils.py", line 103, in execute
    return super().execute(sql, params)
  File "/usr/local/lib/python3.10/site-packages/django/db/backends/utils.py", line 67, in execute
    return self._execute_with_wrappers(
  File "/usr/local/lib/python3.10/site-packages/django/db/backends/utils.py", line 80, in _execute_with_wrappers
    return executor(sql, params, many, context)
  File "/usr/local/lib/python3.10/site-packages/django/db/backends/utils.py", line 84, in _execute
    with self.db.wrap_database_errors:
  File "/usr/local/lib/python3.10/site-packages/django/db/utils.py", line 91, in __exit__
    raise dj_exc_value.with_traceback(traceback) from exc_value
  File "/usr/local/lib/python3.10/site-packages/django/db/backends/utils.py", line 89, in _execute
    return self.cursor.execute(sql, params)
  File "/usr/local/lib/python3.10/site-packages/django/db/backends/sqlite3/base.py", line 357, in execute
    return Database.Cursor.execute(self, query, params)
django.db.utils.OperationalError: no such table: core_customuser

During handling of the above exception, another exception occurred:

Traceback (most recent call last):
  File "/usr/local/lib/python3.10/site-packages/django/core/handlers/exception.py", line 55, in inner
    response = get_response(request)
  File "/usr/local/lib/python3.10/site-packages/django/core/handlers/base.py", line 197, in _get_response
    response = wrapped_callback(request, *callback_args, **callback_kwargs)
  File "/usr/local/lib/python3.10/site-packages/django/views/decorators/csrf.py", line 54, in wrapped_view
    return view_func(*args, **kwargs)
  File "/usr/local/lib/python3.10/site-packages/django/views/generic/base.py", line 103, in view
    return self.dispatch(request, *args, **kwargs)
  File "/usr/local/lib/python3.10/site-packages/rest_framework/views.py", line 509, in dispatch
    response = self.handle_exception(exc)
  File "/usr/local/lib/python3.10/site-packages/rest_framework/views.py", line 469, in handle_exception
    self.raise_uncaught_exception(exc)
  File "/usr/local/lib/python3.10/site-packages/rest_framework/views.py", line 480, in raise_uncaught_exception
    raise exc
  File "/usr/local/lib/python3.10/site-packages/rest_framework/views.py", line 506, in dispatch
    response = handler(request, *args, **kwargs)
  File "/usr/src/app/core/views.py", line 80, in post
    print("HELLO", e.detail)
AttributeError: 'OperationalError' object has no attribute 'detail'
"POST /api/log_in/ HTTP/1.1" 500 195702
Internal Server Error: /api/log_in/
Traceback (most recent call last):
  File "/usr/local/lib/python3.10/site-packages/django/db/backends/utils.py", line 89, in _execute
    return self.cursor.execute(sql, params)
  File "/usr/local/lib/python3.10/site-packages/django/db/backends/sqlite3/base.py", line 357, in execute
    return Database.Cursor.execute(self, query, params)
sqlite3.OperationalError: no such table: core_customuser

The above exception was the direct cause of the following exception:

Traceback (most recent call last):
  File "/usr/src/app/core/views.py", line 76, in post
    serializer.is_valid(raise_exception=True)
  File "/usr/local/lib/python3.10/site-packages/rest_framework/serializers.py", line 227, in is_valid
    self._validated_data = self.run_validation(self.initial_data)
  File "/usr/local/lib/python3.10/site-packages/rest_framework/serializers.py", line 429, in run_validation
    value = self.validate(value)
  File "/usr/local/lib/python3.10/site-packages/rest_framework_simplejwt/serializers.py", line 68, in validate
    data = super().validate(attrs)
  File "/usr/local/lib/python3.10/site-packages/rest_framework_simplejwt/serializers.py", line 49, in validate
    self.user = authenticate(**authenticate_kwargs)
  File "/usr/local/lib/python3.10/site-packages/django/views/decorators/debug.py", line 42, in sensitive_variables_wrapper
    return func(*func_args, **func_kwargs)
  File "/usr/local/lib/python3.10/site-packages/django/contrib/auth/__init__.py", line 77, in authenticate
    user = backend.authenticate(request, **credentials)
  File "/usr/src/app/core/backends.py", line 11, in authenticate
    user = User.objects.get(
  File "/usr/local/lib/python3.10/site-packages/django/db/models/manager.py", line 85, in manager_method
    return getattr(self.get_queryset(), name)(*args, **kwargs)
  File "/usr/local/lib/python3.10/site-packages/django/db/models/query.py", line 646, in get
    num = len(clone)
  File "/usr/local/lib/python3.10/site-packages/django/db/models/query.py", line 376, in __len__
    self._fetch_all()
  File "/usr/local/lib/python3.10/site-packages/django/db/models/query.py", line 1866, in _fetch_all
    self._result_cache = list(self._iterable_class(self))
  File "/usr/local/lib/python3.10/site-packages/django/db/models/query.py", line 87, in __iter__
    results = compiler.execute_sql(
  File "/usr/local/lib/python3.10/site-packages/django/db/models/sql/compiler.py", line 1398, in execute_sql
    cursor.execute(sql, params)
  File "/usr/local/lib/python3.10/site-packages/django/db/backends/utils.py", line 103, in execute
    return super().execute(sql, params)
  File "/usr/local/lib/python3.10/site-packages/django/db/backends/utils.py", line 67, in execute
    return self._execute_with_wrappers(
  File "/usr/local/lib/python3.10/site-packages/django/db/backends/utils.py", line 80, in _execute_with_wrappers
    return executor(sql, params, many, context)
  File "/usr/local/lib/python3.10/site-packages/django/db/backends/utils.py", line 84, in _execute
    with self.db.wrap_database_errors:
  File "/usr/local/lib/python3.10/site-packages/django/db/utils.py", line 91, in __exit__
    raise dj_exc_value.with_traceback(traceback) from exc_value
  File "/usr/local/lib/python3.10/site-packages/django/db/backends/utils.py", line 89, in _execute
    return self.cursor.execute(sql, params)
  File "/usr/local/lib/python3.10/site-packages/django/db/backends/sqlite3/base.py", line 357, in execute
    return Database.Cursor.execute(self, query, params)
django.db.utils.OperationalError: no such table: core_customuser

During handling of the above exception, another exception occurred:

Traceback (most recent call last):
  File "/usr/local/lib/python3.10/site-packages/django/core/handlers/exception.py", line 55, in inner
    response = get_response(request)
  File "/usr/local/lib/python3.10/site-packages/django/core/handlers/base.py", line 197, in _get_response
    response = wrapped_callback(request, *callback_args, **callback_kwargs)
  File "/usr/local/lib/python3.10/site-packages/django/views/decorators/csrf.py", line 54, in wrapped_view
    return view_func(*args, **kwargs)
  File "/usr/local/lib/python3.10/site-packages/django/views/generic/base.py", line 103, in view
    return self.dispatch(request, *args, **kwargs)
  File "/usr/local/lib/python3.10/site-packages/rest_framework/views.py", line 509, in dispatch
    response = self.handle_exception(exc)
  File "/usr/local/lib/python3.10/site-packages/rest_framework/views.py", line 469, in handle_exception
    self.raise_uncaught_exception(exc)
  File "/usr/local/lib/python3.10/site-packages/rest_framework/views.py", line 480, in raise_uncaught_exception
    raise exc
  File "/usr/local/lib/python3.10/site-packages/rest_framework/views.py", line 506, in dispatch
    response = handler(request, *args, **kwargs)
  File "/usr/src/app/core/views.py", line 80, in post
    print("HELLO", e.detail)
AttributeError: 'OperationalError' object has no attribute 'detail'
"POST /api/log_in/ HTTP/1.1" 500 195702
Internal Server Error: /api/log_in/
Traceback (most recent call last):
  File "/usr/local/lib/python3.10/site-packages/django/db/backends/utils.py", line 89, in _execute
    return self.cursor.execute(sql, params)
  File "/usr/local/lib/python3.10/site-packages/django/db/backends/sqlite3/base.py", line 357, in execute
    return Database.Cursor.execute(self, query, params)
sqlite3.OperationalError: no such table: core_customuser

The above exception was the direct cause of the following exception:

Traceback (most recent call last):
  File "/usr/src/app/core/views.py", line 76, in post
    serializer.is_valid(raise_exception=True)
  File "/usr/local/lib/python3.10/site-packages/rest_framework/serializers.py", line 227, in is_valid
    self._validated_data = self.run_validation(self.initial_data)
  File "/usr/local/lib/python3.10/site-packages/rest_framework/serializers.py", line 429, in run_validation
    value = self.validate(value)
  File "/usr/local/lib/python3.10/site-packages/rest_framework_simplejwt/serializers.py", line 68, in validate
    data = super().validate(attrs)
  File "/usr/local/lib/python3.10/site-packages/rest_framework_simplejwt/serializers.py", line 49, in validate
    self.user = authenticate(**authenticate_kwargs)
  File "/usr/local/lib/python3.10/site-packages/django/views/decorators/debug.py", line 42, in sensitive_variables_wrapper
    return func(*func_args, **func_kwargs)
  File "/usr/local/lib/python3.10/site-packages/django/contrib/auth/__init__.py", line 77, in authenticate
    user = backend.authenticate(request, **credentials)
  File "/usr/src/app/core/backends.py", line 11, in authenticate
    user = User.objects.get(
  File "/usr/local/lib/python3.10/site-packages/django/db/models/manager.py", line 85, in manager_method
    return getattr(self.get_queryset(), name)(*args, **kwargs)
  File "/usr/local/lib/python3.10/site-packages/django/db/models/query.py", line 646, in get
    num = len(clone)
  File "/usr/local/lib/python3.10/site-packages/django/db/models/query.py", line 376, in __len__
    self._fetch_all()
  File "/usr/local/lib/python3.10/site-packages/django/db/models/query.py", line 1866, in _fetch_all
    self._result_cache = list(self._iterable_class(self))
  File "/usr/local/lib/python3.10/site-packages/django/db/models/query.py", line 87, in __iter__
    results = compiler.execute_sql(
  File "/usr/local/lib/python3.10/site-packages/django/db/models/sql/compiler.py", line 1398, in execute_sql
    cursor.execute(sql, params)
  File "/usr/local/lib/python3.10/site-packages/django/db/backends/utils.py", line 103, in execute
    return super().execute(sql, params)
  File "/usr/local/lib/python3.10/site-packages/django/db/backends/utils.py", line 67, in execute
    return self._execute_with_wrappers(
  File "/usr/local/lib/python3.10/site-packages/django/db/backends/utils.py", line 80, in _execute_with_wrappers
    return executor(sql, params, many, context)
  File "/usr/local/lib/python3.10/site-packages/django/db/backends/utils.py", line 84, in _execute
    with self.db.wrap_database_errors:
  File "/usr/local/lib/python3.10/site-packages/django/db/utils.py", line 91, in __exit__
    raise dj_exc_value.with_traceback(traceback) from exc_value
  File "/usr/local/lib/python3.10/site-packages/django/db/backends/utils.py", line 89, in _execute
    return self.cursor.execute(sql, params)
  File "/usr/local/lib/python3.10/site-packages/django/db/backends/sqlite3/base.py", line 357, in execute
    return Database.Cursor.execute(self, query, params)
django.db.utils.OperationalError: no such table: core_customuser

During handling of the above exception, another exception occurred:

Traceback (most recent call last):
  File "/usr/local/lib/python3.10/site-packages/django/core/handlers/exception.py", line 55, in inner
    response = get_response(request)
  File "/usr/local/lib/python3.10/site-packages/django/core/handlers/base.py", line 197, in _get_response
    response = wrapped_callback(request, *callback_args, **callback_kwargs)
  File "/usr/local/lib/python3.10/site-packages/django/views/decorators/csrf.py", line 54, in wrapped_view
    return view_func(*args, **kwargs)
  File "/usr/local/lib/python3.10/site-packages/django/views/generic/base.py", line 103, in view
    return self.dispatch(request, *args, **kwargs)
  File "/usr/local/lib/python3.10/site-packages/rest_framework/views.py", line 509, in dispatch
    response = self.handle_exception(exc)
  File "/usr/local/lib/python3.10/site-packages/rest_framework/views.py", line 469, in handle_exception
    self.raise_uncaught_exception(exc)
  File "/usr/local/lib/python3.10/site-packages/rest_framework/views.py", line 480, in raise_uncaught_exception
    raise exc
  File "/usr/local/lib/python3.10/site-packages/rest_framework/views.py", line 506, in dispatch
    response = handler(request, *args, **kwargs)
  File "/usr/src/app/core/views.py", line 80, in post
    print("HELLO", e.detail)
AttributeError: 'OperationalError' object has no attribute 'detail'
"POST /api/log_in/ HTTP/1.1" 500 195702
Internal Server Error: /api/trial-days/
Traceback (most recent call last):
  File "/usr/local/lib/python3.10/site-packages/django/db/backends/utils.py", line 89, in _execute
    return self.cursor.execute(sql, params)
psycopg2.errors.UndefinedTable: relation "core_trialdays" does not exist
LINE 1: ...ore_trialdays"."id", "core_trialdays"."days" FROM "core_tria...
                                                             ^


The above exception was the direct cause of the following exception:

Traceback (most recent call last):
  File "/usr/local/lib/python3.10/site-packages/django/core/handlers/exception.py", line 55, in inner
    response = get_response(request)
  File "/usr/local/lib/python3.10/site-packages/django/core/handlers/base.py", line 197, in _get_response
    response = wrapped_callback(request, *callback_args, **callback_kwargs)
  File "/usr/local/lib/python3.10/site-packages/django/views/decorators/csrf.py", line 54, in wrapped_view
    return view_func(*args, **kwargs)
  File "/usr/local/lib/python3.10/site-packages/django/views/generic/base.py", line 103, in view
    return self.dispatch(request, *args, **kwargs)
  File "/usr/local/lib/python3.10/site-packages/rest_framework/views.py", line 509, in dispatch
    response = self.handle_exception(exc)
  File "/usr/local/lib/python3.10/site-packages/rest_framework/views.py", line 469, in handle_exception
    self.raise_uncaught_exception(exc)
  File "/usr/local/lib/python3.10/site-packages/rest_framework/views.py", line 480, in raise_uncaught_exception
    raise exc
  File "/usr/local/lib/python3.10/site-packages/rest_framework/views.py", line 506, in dispatch
    response = handler(request, *args, **kwargs)
  File "/usr/src/app/core/views.py", line 261, in get
    return Response(serializer.data)
  File "/usr/local/lib/python3.10/site-packages/rest_framework/serializers.py", line 768, in data
    ret = super().data
  File "/usr/local/lib/python3.10/site-packages/rest_framework/serializers.py", line 253, in data
    self._data = self.to_representation(self.instance)
  File "/usr/local/lib/python3.10/site-packages/rest_framework/serializers.py", line 686, in to_representation
    return [
  File "/usr/local/lib/python3.10/site-packages/django/db/models/query.py", line 394, in __iter__
    self._fetch_all()
  File "/usr/local/lib/python3.10/site-packages/django/db/models/query.py", line 1866, in _fetch_all
    self._result_cache = list(self._iterable_class(self))
  File "/usr/local/lib/python3.10/site-packages/django/db/models/query.py", line 87, in __iter__
    results = compiler.execute_sql(
  File "/usr/local/lib/python3.10/site-packages/django/db/models/sql/compiler.py", line 1398, in execute_sql
    cursor.execute(sql, params)
  File "/usr/local/lib/python3.10/site-packages/django/db/backends/utils.py", line 103, in execute
    return super().execute(sql, params)
  File "/usr/local/lib/python3.10/site-packages/django/db/backends/utils.py", line 67, in execute
    return self._execute_with_wrappers(
  File "/usr/local/lib/python3.10/site-packages/django/db/backends/utils.py", line 80, in _execute_with_wrappers
    return executor(sql, params, many, context)
  File "/usr/local/lib/python3.10/site-packages/django/db/backends/utils.py", line 84, in _execute
    with self.db.wrap_database_errors:
  File "/usr/local/lib/python3.10/site-packages/django/db/utils.py", line 91, in __exit__
    raise dj_exc_value.with_traceback(traceback) from exc_value
  File "/usr/local/lib/python3.10/site-packages/django/db/backends/utils.py", line 89, in _execute
    return self.cursor.execute(sql, params)
django.db.utils.ProgrammingError: relation "core_trialdays" does not exist
LINE 1: ...ore_trialdays"."id", "core_trialdays"."days" FROM "core_tria...
                                                             ^

"GET /api/trial-days/ HTTP/1.1" 500 149420
Internal Server Error: /api/log_in/
Traceback (most recent call last):
  File "/usr/local/lib/python3.10/site-packages/django/db/backends/utils.py", line 89, in _execute
    return self.cursor.execute(sql, params)
psycopg2.errors.UndefinedTable: relation "core_customuser" does not exist
LINE 1: ...subscription_id", "core_customuser"."active" FROM "core_cust...
                                                             ^


The above exception was the direct cause of the following exception:

Traceback (most recent call last):
  File "/usr/src/app/core/views.py", line 76, in post
    serializer.is_valid(raise_exception=True)
  File "/usr/local/lib/python3.10/site-packages/rest_framework/serializers.py", line 227, in is_valid
    self._validated_data = self.run_validation(self.initial_data)
  File "/usr/local/lib/python3.10/site-packages/rest_framework/serializers.py", line 429, in run_validation
    value = self.validate(value)
  File "/usr/local/lib/python3.10/site-packages/rest_framework_simplejwt/serializers.py", line 68, in validate
    data = super().validate(attrs)
  File "/usr/local/lib/python3.10/site-packages/rest_framework_simplejwt/serializers.py", line 49, in validate
    self.user = authenticate(**authenticate_kwargs)
  File "/usr/local/lib/python3.10/site-packages/django/views/decorators/debug.py", line 42, in sensitive_variables_wrapper
    return func(*func_args, **func_kwargs)
  File "/usr/local/lib/python3.10/site-packages/django/contrib/auth/__init__.py", line 77, in authenticate
    user = backend.authenticate(request, **credentials)
  File "/usr/src/app/core/backends.py", line 11, in authenticate
    user = User.objects.get(
  File "/usr/local/lib/python3.10/site-packages/django/db/models/manager.py", line 85, in manager_method
    return getattr(self.get_queryset(), name)(*args, **kwargs)
  File "/usr/local/lib/python3.10/site-packages/django/db/models/query.py", line 646, in get
    num = len(clone)
  File "/usr/local/lib/python3.10/site-packages/django/db/models/query.py", line 376, in __len__
    self._fetch_all()
  File "/usr/local/lib/python3.10/site-packages/django/db/models/query.py", line 1866, in _fetch_all
    self._result_cache = list(self._iterable_class(self))
  File "/usr/local/lib/python3.10/site-packages/django/db/models/query.py", line 87, in __iter__
    results = compiler.execute_sql(
  File "/usr/local/lib/python3.10/site-packages/django/db/models/sql/compiler.py", line 1398, in execute_sql
    cursor.execute(sql, params)
  File "/usr/local/lib/python3.10/site-packages/django/db/backends/utils.py", line 103, in execute
    return super().execute(sql, params)
  File "/usr/local/lib/python3.10/site-packages/django/db/backends/utils.py", line 67, in execute
    return self._execute_with_wrappers(
  File "/usr/local/lib/python3.10/site-packages/django/db/backends/utils.py", line 80, in _execute_with_wrappers
    return executor(sql, params, many, context)
  File "/usr/local/lib/python3.10/site-packages/django/db/backends/utils.py", line 84, in _execute
    with self.db.wrap_database_errors:
  File "/usr/local/lib/python3.10/site-packages/django/db/utils.py", line 91, in __exit__
    raise dj_exc_value.with_traceback(traceback) from exc_value
  File "/usr/local/lib/python3.10/site-packages/django/db/backends/utils.py", line 89, in _execute
    return self.cursor.execute(sql, params)
django.db.utils.ProgrammingError: relation "core_customuser" does not exist
LINE 1: ...subscription_id", "core_customuser"."active" FROM "core_cust...
                                                             ^


During handling of the above exception, another exception occurred:

Traceback (most recent call last):
  File "/usr/local/lib/python3.10/site-packages/django/core/handlers/exception.py", line 55, in inner
    response = get_response(request)
  File "/usr/local/lib/python3.10/site-packages/django/core/handlers/base.py", line 197, in _get_response
    response = wrapped_callback(request, *callback_args, **callback_kwargs)
  File "/usr/local/lib/python3.10/site-packages/django/views/decorators/csrf.py", line 54, in wrapped_view
    return view_func(*args, **kwargs)
  File "/usr/local/lib/python3.10/site-packages/django/views/generic/base.py", line 103, in view
    return self.dispatch(request, *args, **kwargs)
  File "/usr/local/lib/python3.10/site-packages/rest_framework/views.py", line 509, in dispatch
    response = self.handle_exception(exc)
  File "/usr/local/lib/python3.10/site-packages/rest_framework/views.py", line 469, in handle_exception
    self.raise_uncaught_exception(exc)
  File "/usr/local/lib/python3.10/site-packages/rest_framework/views.py", line 480, in raise_uncaught_exception
    raise exc
  File "/usr/local/lib/python3.10/site-packages/rest_framework/views.py", line 506, in dispatch
    response = handler(request, *args, **kwargs)
  File "/usr/src/app/core/views.py", line 80, in post
    print("HELLO", e.detail)
AttributeError: 'ProgrammingError' object has no attribute 'detail'
"POST /api/log_in/ HTTP/1.1" 500 187466
Login error: No active account found with the given credentials
Traceback (most recent call last):
  File "/usr/src/app/core/views.py", line 81, in post
    serializer.is_valid(raise_exception=True)
  File "/usr/local/lib/python3.10/site-packages/rest_framework/serializers.py", line 227, in is_valid
    self._validated_data = self.run_validation(self.initial_data)
  File "/usr/local/lib/python3.10/site-packages/rest_framework/serializers.py", line 429, in run_validation
    value = self.validate(value)
  File "/usr/local/lib/python3.10/site-packages/rest_framework_simplejwt/serializers.py", line 68, in validate
    data = super().validate(attrs)
  File "/usr/local/lib/python3.10/site-packages/rest_framework_simplejwt/serializers.py", line 52, in validate
    raise exceptions.AuthenticationFailed(
rest_framework.exceptions.AuthenticationFailed: No active account found with the given credentials
INFO 2024-04-21 11:01:51,978 autoreload Watching for file changes with StatReloader
INFO 2024-04-21 11:02:27,434 basehttp "POST /api/log_in/ HTTP/1.1" 200 1070
INFO 2024-04-21 11:02:27,466 views Retrieved all trial days.
INFO 2024-04-21 11:02:27,472 basehttp "GET /api/trial-days/ HTTP/1.1" 200 2
INFO 2024-04-21 11:02:29,796 basehttp "OPTIONS /api/get_product_prices/ HTTP/1.1" 200 0
INFO 2024-04-21 11:02:29,797 basehttp "OPTIONS /api/payment_method/1/ HTTP/1.1" 200 0
INFO 2024-04-21 11:02:30,376 views Retrieved payment methods for user 1
INFO 2024-04-21 11:02:30,377 basehttp "GET /api/payment_method/1/ HTTP/1.1" 200 56
INFO 2024-04-21 11:02:30,552 views Retrieved product prices successfully.
INFO 2024-04-21 11:02:30,553 basehttp "GET /api/get_product_prices/ HTTP/1.1" 200 1399
INFO 2024-04-21 11:02:50,096 basehttp "OPTIONS /api/create_subscription/1/ HTTP/1.1" 200 0
INFO 2024-04-21 11:02:51,251 views Stripe event payment_method.attached received with ID evt_1P82qtJQ5QjlwW1LlzZcGp2q
INFO 2024-04-21 11:02:51,262 views Processed new Stripe event evt_1P82qtJQ5QjlwW1LlzZcGp2q.
INFO 2024-04-21 11:02:51,262 basehttp "POST /stripe/webhook/ HTTP/1.1" 200 0
INFO 2024-04-21 11:02:51,569 views Stripe event customer.updated received with ID evt_1P82qtJQ5QjlwW1L70ft7GBT
INFO 2024-04-21 11:02:51,579 views Processed new Stripe event evt_1P82qtJQ5QjlwW1L70ft7GBT.
INFO 2024-04-21 11:02:51,581 basehttp "POST /stripe/webhook/ HTTP/1.1" 200 0
INFO 2024-04-21 11:02:53,655 views New subscription created for user 1
INFO 2024-04-21 11:02:53,656 basehttp "POST /api/create_subscription/1/ HTTP/1.1" 201 132
INFO 2024-04-21 11:02:53,706 basehttp "OPTIONS /api/users/1/ HTTP/1.1" 200 0
INFO 2024-04-21 11:02:53,719 basehttp "GET /api/users/1/ HTTP/1.1" 200 241
INFO 2024-04-21 11:02:53,831 views Stripe event charge.succeeded received with ID evt_3P82qtJQ5QjlwW1L0nSOPXnu
INFO 2024-04-21 11:02:53,841 views Processed new Stripe event evt_3P82qtJQ5QjlwW1L0nSOPXnu.
INFO 2024-04-21 11:02:53,843 basehttp "POST /stripe/webhook/ HTTP/1.1" 200 0
INFO 2024-04-21 11:02:53,908 views Stripe event customer.updated received with ID evt_1P82qvJQ5QjlwW1LIeS18kyo
INFO 2024-04-21 11:02:53,918 views Processed new Stripe event evt_1P82qvJQ5QjlwW1LIeS18kyo.
INFO 2024-04-21 11:02:53,919 basehttp "POST /stripe/webhook/ HTTP/1.1" 200 0
INFO 2024-04-21 11:02:54,060 views Stripe event customer.subscription.created received with ID evt_1P82qvJQ5QjlwW1Lv6QAVLOS
INFO 2024-04-21 11:02:54,070 views Processed new Stripe event evt_1P82qvJQ5QjlwW1Lv6QAVLOS.
INFO 2024-04-21 11:02:54,071 basehttp "POST /stripe/webhook/ HTTP/1.1" 200 0
INFO 2024-04-21 11:02:54,180 views Stripe event payment_intent.succeeded received with ID evt_3P82qtJQ5QjlwW1L03YWhwOZ
INFO 2024-04-21 11:02:54,188 views Processed new Stripe event evt_3P82qtJQ5QjlwW1L03YWhwOZ.
INFO 2024-04-21 11:02:54,189 basehttp "POST /stripe/webhook/ HTTP/1.1" 200 0
INFO 2024-04-21 11:02:54,248 views Stripe event payment_intent.created received with ID evt_3P82qtJQ5QjlwW1L0BydxehF
INFO 2024-04-21 11:02:54,258 views Processed new Stripe event evt_3P82qtJQ5QjlwW1L0BydxehF.
INFO 2024-04-21 11:02:54,258 basehttp "POST /stripe/webhook/ HTTP/1.1" 200 0
INFO 2024-04-21 11:02:54,372 views Stripe event invoice.created received with ID evt_1P82qwJQ5QjlwW1LaUROmZ2W
INFO 2024-04-21 11:02:54,382 views Processed new Stripe event evt_1P82qwJQ5QjlwW1LaUROmZ2W.
INFO 2024-04-21 11:02:54,383 basehttp "POST /stripe/webhook/ HTTP/1.1" 200 0
INFO 2024-04-21 11:02:54,455 views Stripe event invoice.finalized received with ID evt_1P82qwJQ5QjlwW1LCFU4HaVR
INFO 2024-04-21 11:02:54,465 views Processed new Stripe event evt_1P82qwJQ5QjlwW1LCFU4HaVR.
INFO 2024-04-21 11:02:54,466 basehttp "POST /stripe/webhook/ HTTP/1.1" 200 0
INFO 2024-04-21 11:02:54,563 views Stripe event invoice.paid received with ID evt_1P82qwJQ5QjlwW1LV5Vpuwxc
INFO 2024-04-21 11:02:54,574 views Processed new Stripe event evt_1P82qwJQ5QjlwW1LV5Vpuwxc.
INFO 2024-04-21 11:02:54,575 basehttp "POST /stripe/webhook/ HTTP/1.1" 200 0
INFO 2024-04-21 11:02:54,646 views Stripe event invoice.payment_succeeded received with ID evt_1P82qwJQ5QjlwW1LYcuXZ2kF
ERROR 2024-04-21 11:02:55,136 views Error processing Stripe webhook for event evt_1P82qwJQ5QjlwW1LYcuXZ2kF: Connection unexpectedly closed
Traceback (most recent call last):
  File "/usr/src/app/payments/views.py", line 383, in post
    self.send_invoice_email(customer_email, invoice)
  File "/usr/src/app/payments/views.py", line 529, in send_invoice_email
    send_mail(
  File "/usr/local/lib/python3.10/site-packages/django/core/mail/__init__.py", line 87, in send_mail
    return mail.send()
  File "/usr/local/lib/python3.10/site-packages/django/core/mail/message.py", line 298, in send
    return self.get_connection(fail_silently).send_messages([self])
  File "/usr/local/lib/python3.10/site-packages/django/core/mail/backends/smtp.py", line 124, in send_messages
    new_conn_created = self.open()
  File "/usr/local/lib/python3.10/site-packages/django/core/mail/backends/smtp.py", line 91, in open
    self.connection.login(self.username, self.password)
  File "/usr/local/lib/python3.10/smtplib.py", line 739, in login
    (code, resp) = self.auth(
  File "/usr/local/lib/python3.10/smtplib.py", line 642, in auth
    (code, resp) = self.docmd("AUTH", mechanism + " " + response)
  File "/usr/local/lib/python3.10/smtplib.py", line 432, in docmd
    return self.getreply()
  File "/usr/local/lib/python3.10/smtplib.py", line 405, in getreply
    raise SMTPServerDisconnected("Connection unexpectedly closed")
smtplib.SMTPServerDisconnected: Connection unexpectedly closed
ERROR 2024-04-21 11:02:55,138 log Internal Server Error: /stripe/webhook/
ERROR 2024-04-21 11:02:55,139 basehttp "POST /stripe/webhook/ HTTP/1.1" 500 43
INFO 2024-04-21 11:02:55,678 views Subscription details retrieved for user 1
INFO 2024-04-21 11:02:55,679 basehttp "GET /api/create_subscription/1/ HTTP/1.1" 200 193
INFO 2024-04-21 11:02:55,953 views Retrieved payment methods for user 1
INFO 2024-04-21 11:02:55,954 basehttp "GET /api/payment_method/1/ HTTP/1.1" 200 1502
INFO 2024-04-21 11:22:28,126 views Retrieved all trial days.
INFO 2024-04-21 11:22:28,132 basehttp "GET /api/trial-days/ HTTP/1.1" 200 2
